<?xml version='1.0' encoding='utf-8'?>
<robot xmlns:xacro="http://ros.org/wiki/xacro" name="gen3_arm">

  
  <xacro:property name="last_arm_link" value="end_effector_link" />
  <xacro:property name="PI" value="3.1415926535897931" />

  <xacro:macro name="load_arm" params="
    parent
    dof
    vision
    prefix
    *origin
    robot_ip
    username:=admin
    password:=admin
    port:=10000
    port_realtime:=10001
    session_inactivity_timeout_ms:=6000
    connection_inactivity_timeout_ms:=2000
    use_internal_bus_gripper_comm:=true
    gripper_joint_name
    gripper_max_velocity:=100.0
    gripper_max_force:=100.0
    use_fake_hardware:=false
    fake_sensor_commands:=false
    sim_gazebo:=false
    sim_ignition:=false
    sim_isaac:=false
    isaac_joint_commands:=/isaac_joint_commands
    isaac_joint_states:=/isaac_joint_states
    use_external_cable:=false
    initial_positions:=${dict(joint_1=0.0,joint_2=0.0,joint_3=0.0,joint_4=0.0,joint_5=0.0,joint_6=0.0,joint_7=0.0)}
    moveit_active:=false">

    <!-- ros2 control include -->
    <xacro:include filename="$(find kortex_description)/arms/gen3/${dof}dof/urdf/kortex.ros2_control.xacro" />

   <xacro:kortex_ros2_control name="${prefix}KortexMultiInterfaceHardware"
			prefix="${prefix}"
			use_fake_hardware="${use_fake_hardware}"
			fake_sensor_commands="${fake_sensor_commands}"
			sim_gazebo="${sim_gazebo}"
			sim_ignition="${sim_ignition}"
			sim_isaac="${sim_isaac}"
			isaac_joint_commands="${isaac_joint_commands}"
			isaac_joint_states="${isaac_joint_states}"
			tf_prefix=""
			initial_positions="${initial_positions}"
			robot_ip="${robot_ip}"
			username="${username}"
			password="${password}"
			port="${port}"
			port_realtime="${port_realtime}"
			session_inactivity_timeout_ms="${session_inactivity_timeout_ms}"
			connection_inactivity_timeout_ms="${connection_inactivity_timeout_ms}"
			use_internal_bus_gripper_comm="${use_internal_bus_gripper_comm}"
			gripper_max_velocity="${gripper_max_velocity}"
			gripper_max_force="${gripper_max_force}"
			gripper_joint_name="${gripper_joint_name}"
			/>

    <joint name="${prefix}base_joint" type="fixed">
      <xacro:insert_block name="origin" />
      <parent link="${parent}" />
      <child link="${prefix}base_link" />
    </joint>
    <link name="${prefix}base_link">
      <inertial>
        <origin xyz="-0.000648 -0.000166 0.084487" rpy="0 0 0" />
        <mass value="1.697" />
        <inertia ixx="0.004622" ixy="9E-06" ixz="6E-05" iyy="0.004495" iyz="9E-06" izz="0.002079" />
      </inertial>
      <visual>
        <origin xyz="0 0 0" rpy="0 0 0" />
        <geometry>
          <mesh filename="file://$(find kortex_description)/arms/gen3/${dof}dof/meshes/base_link.dae" />
        </geometry>
        <material name="">
          <color rgba="0.75294 0.75294 0.75294 1" />
        </material>
      </visual>
      <collision>
        <origin xyz="0 0 0" rpy="0 0 0" />
        <geometry>
          <mesh filename="file://$(find kortex_description)/arms/gen3/${dof}dof/meshes/base_link.dae" />
        </geometry>
      </collision>
    </link>
    <link name="${prefix}shoulder_link">
      <inertial>
        <origin xyz="-2.3E-05 -0.010364 -0.07336" rpy="0 0 0" />
        <mass value="1.3773" />
        <inertia ixx="0.00457" ixy="1E-06" ixz="2E-06" iyy="0.004831" iyz="0.000448" izz="0.001409" />
      </inertial>
      <visual>
        <origin xyz="0 0 0" rpy="0 0 0" />
        <geometry>
          <mesh filename="file://$(find kortex_description)/arms/gen3/${dof}dof/meshes/shoulder_link.dae" />
        </geometry>
        <material name="">
          <color rgba="0.75294 0.75294 0.75294 1" />
        </material>
      </visual>
      <collision>
        <origin xyz="0 0 0" rpy="0 0 0" />
        <geometry>
          <mesh filename="file://$(find kortex_description)/arms/gen3/${dof}dof/meshes/shoulder_link.dae" />
        </geometry>
      </collision>
    </link>
    <xacro:if value="${use_external_cable}">
      <joint name="${prefix}joint_1" type="revolute">
        <origin xyz="-0.0004758 0.0002877949192149348 0.1571216021142782" rpy="3.139021497201073 3.1907817652109734e-05 -0.0010640000025041456" />
        <parent link="${prefix}base_link" />
        <child link="${prefix}shoulder_link" />
        <axis xyz="0 0 1" />
        <limit lower="${-2*PI}" upper="${2*PI}" effort="39" velocity="1.3963" />
      </joint>
    </xacro:if>
    <xacro:unless value="${use_external_cable}">
      <joint name="${prefix}joint_1" type="continuous">
        <origin xyz="-0.0004758 0.0002877949192149348 0.1571216021142782" rpy="3.139021497201073 3.1907817652109734e-05 -0.0010640000025041456" />
        <parent link="${prefix}base_link" />
        <child link="${prefix}shoulder_link" />
        <axis xyz="0 0 1" />
        <limit effort="39" velocity="1.3963" />
      </joint>
    </xacro:unless>
    <link name="${prefix}half_arm_1_link">
      <inertial>
        <origin xyz="-4.4E-05 -0.09958 -0.013278" rpy="0 0 0" />
        <mass value="1.1636" />
        <inertia ixx="0.011088" ixy="5E-06" ixz="0" iyy="0.001072" iyz="-0.000691" izz="0.011255" />
      </inertial>
      <visual>
        <origin xyz="0 0 0" rpy="0 0 0" />
        <geometry>
          <mesh filename="file://$(find kortex_description)/arms/gen3/${dof}dof/meshes/half_arm_1_link.dae" />
        </geometry>
        <material name="">
          <color rgba="0.75294 0.75294 0.75294 1" />
        </material>
      </visual>
      <collision>
        <origin xyz="0 0 0" rpy="0 0 0" />
        <geometry>
          <mesh filename="file://$(find kortex_description)/arms/gen3/${dof}dof/meshes/half_arm_1_link.dae" />
        </geometry>
      </collision>
    </link>
    <joint name="${prefix}joint_2" type="revolute">
      <origin xyz="-2.0000000000000063e-06 0.005450002549203835 -0.12907399972450492" rpy="1.5703364989748514 -0.002088903255911073 0.00046779336884090973" />
      <parent link="${prefix}shoulder_link" />
      <child link="${prefix}half_arm_1_link" />
      <axis xyz="0 0 1" />
      <limit lower="-2.41" upper="2.41" effort="39" velocity="1.3963" />
    </joint>
    <link name="${prefix}half_arm_2_link">
      <inertial>
        <origin xyz="-4.4E-05 -0.006641 -0.117892" rpy="0 0 0" />
        <mass value="1.1636" />
        <inertia ixx="0.010932" ixy="0" ixz="-7E-06" iyy="0.011127" iyz="0.000606" izz="0.001043" />
      </inertial>
      <visual>
        <origin xyz="0 0 0" rpy="0 0 0" />
        <geometry>
          <mesh filename="file://$(find kortex_description)/arms/gen3/${dof}dof/meshes/half_arm_2_link.dae" />
        </geometry>
        <material name="">
          <color rgba="0.75294 0.75294 0.75294 1" />
        </material>
      </visual>
      <collision>
        <origin xyz="0 0 0" rpy="0 0 0" />
        <geometry>
          <mesh filename="file://$(find kortex_description)/arms/gen3/${dof}dof/meshes/half_arm_2_link.dae" />
        </geometry>
      </collision>
    </link>
    <xacro:if value="${use_external_cable}">
      <joint name="${prefix}joint_3" type="revolute">
        <origin xyz="7.659999999999975e-05 -0.21127250028466737 -0.006452496721663922" rpy="-1.567683786723792 -0.0023201991943602516 0.0007858107182518457" />
        <parent link="${prefix}half_arm_1_link" />
        <child link="${prefix}half_arm_2_link" />
        <axis xyz="0 0 1" />
        <limit lower="${-2*PI}" upper="${2*PI}" effort="39" velocity="1.3963" />
      </joint>
    </xacro:if>
    <xacro:unless value="${use_external_cable}">
      <joint name="${prefix}joint_3" type="continuous">
        <origin xyz="7.659999999999975e-05 -0.21127250028466737 -0.006452496721663922" rpy="-1.567683786723792 -0.0023201991943602516 0.0007858107182518457" />
        <parent link="${prefix}half_arm_1_link" />
        <child link="${prefix}half_arm_2_link" />
        <axis xyz="0 0 1" />
        <limit effort="39" velocity="1.3963" />
      </joint>
    </xacro:unless>
    <link name="${prefix}forearm_link">
      <inertial>
        <origin xyz="-1.8E-05 -0.075478 -0.015006" rpy="0 0 0" />
        <mass value="0.9302" />
        <inertia ixx="0.008147" ixy="-1E-06" ixz="0" iyy="0.000631" iyz="-0.0005" izz="0.008316" />
      </inertial>
      <visual>
        <origin xyz="0 0 0" rpy="0 0 0" />
        <geometry>
          <mesh filename="file://$(find kortex_description)/arms/gen3/${dof}dof/meshes/forearm_link.dae" />
        </geometry>
        <material name="">
          <color rgba="0.75294 0.75294 0.75294 1" />
        </material>
      </visual>
      <collision>
        <origin xyz="0 0 0" rpy="0 0 0" />
        <geometry>
          <mesh filename="file://$(find kortex_description)/arms/gen3/${dof}dof/meshes/forearm_link.dae" />
        </geometry>
      </collision>
    </link>
    <joint name="${prefix}joint_4" type="revolute">
      <origin xyz="9.079999999999996e-05 0.005834903277971877 -0.21127240198389208" rpy="1.572917645816731 -0.006452435120277355 -0.0025743800564759192" />
      <parent link="${prefix}half_arm_2_link" />
      <child link="${prefix}forearm_link" />
      <axis xyz="0 0 1" />
      <limit lower="-2.66" upper="2.66" effort="39" velocity="1.3963" />
    </joint>
    <link name="${prefix}spherical_wrist_1_link">
      <inertial>
        <origin xyz="1E-06 -0.009432 -0.063883" rpy="0 0 0" />
        <mass value="0.6781" />
        <inertia ixx="0.001596" ixy="0" ixz="0" iyy="0.001607" iyz="0.000256" izz="0.000399" />
      </inertial>
      <visual>
        <origin xyz="0 0 0" rpy="0 0 0" />
        <geometry>
          <mesh filename="file://$(find kortex_description)/arms/gen3/${dof}dof/meshes/spherical_wrist_1_link.dae" />
        </geometry>
        <material name="">
          <color rgba="0.75294 0.75294 0.75294 1" />
        </material>
      </visual>
      <collision>
        <origin xyz="0 0 0" rpy="0 0 0" />
        <geometry>
          <mesh filename="file://$(find kortex_description)/arms/gen3/${dof}dof/meshes/spherical_wrist_1_link.dae" />
        </geometry>
      </collision>
    </link>
    <xacro:if value="${use_external_cable}">
      <joint name="${prefix}joint_5" type="revolute">
        <origin xyz="0.0003646000000000001 -0.2093617980065453 -0.005832296577311146" rpy="-1.5741152791051263 0.006632849357796652 0.00024688106273112987" />
        <parent link="${prefix}forearm_link" />
        <child link="${prefix}spherical_wrist_1_link" />
        <axis xyz="0 0 1" />
        <limit lower="${-2*PI}" upper="${2*PI}" effort="9" velocity="1.2218" />
      </joint>
    </xacro:if>
    <xacro:unless value="${use_external_cable}">
      <joint name="${prefix}joint_5" type="continuous">
        <origin xyz="0.0003646000000000001 -0.2093617980065453 -0.005832296577311146" rpy="-1.5741152791051263 0.006632849357796652 0.00024688106273112987" />
        <parent link="${prefix}forearm_link" />
        <child link="${prefix}spherical_wrist_1_link" />
        <axis xyz="0 0 1" />
        <limit effort="9" velocity="1.2218" />
      </joint>
    </xacro:unless>
    <link name="${prefix}spherical_wrist_2_link">
      <inertial>
        <origin xyz="1E-06 -0.045483 -0.00965" rpy="0 0 0" />
        <mass value="0.6781" />
        <inertia ixx="0.001641" ixy="0" ixz="0" iyy="0.00041" iyz="-0.000278" izz="0.001641" />
      </inertial>
      <visual>
        <origin xyz="0 0 0" rpy="0 0 0" />
        <geometry>
          <mesh filename="file://$(find kortex_description)/arms/gen3/${dof}dof/meshes/spherical_wrist_2_link.dae" />
        </geometry>
        <material name="">
          <color rgba="0.75294 0.75294 0.75294 1" />
        </material>
      </visual>
      <collision>
        <origin xyz="0 0 0" rpy="0 0 0" />
        <geometry>
          <mesh filename="file://$(find kortex_description)/arms/gen3/${dof}dof/meshes/spherical_wrist_2_link.dae" />
        </geometry>
      </collision>
    </link>
    <joint name="${prefix}joint_6" type="revolute">
      <origin xyz="-0.00018180000000000084 7.305342306052542e-05 -0.10686190037466063" rpy="1.5775184481445612 -0.005388150467089543 0.0066128245252635885" />
      <parent link="${prefix}spherical_wrist_1_link" />
      <child link="${prefix}spherical_wrist_2_link" />
      <axis xyz="0 0 1" />
      <limit lower="-2.23" upper="2.23" effort="9" velocity="1.2218" />
    </joint>
    <xacro:if value="${vision}">
    <link name="${prefix}bracelet_link">
      <inertial>
        <origin xyz="0.000281 0.011402 -0.029798" rpy="0 0 0" />
        <mass value="0.5" />
        <inertia ixx="0.000587" ixy="3E-06" ixz="3E-06" iyy="0.000369" iyz="-0.000118" izz="0.000609" />
      </inertial>
      <visual>
        <origin xyz="0 0 0" rpy="0 0 0" />
        <geometry>
          <mesh filename="file://$(find kortex_description)/arms/gen3/${dof}dof/meshes/bracelet_with_vision_link.dae" />
        </geometry>
        <material name="">
          <color rgba="0.75294 0.75294 0.75294 1" />
        </material>
      </visual>
      <collision>
        <origin xyz="0 0 0" rpy="0 0 0" />
        <geometry>
          <mesh filename="file://$(find kortex_description)/arms/gen3/${dof}dof/meshes/bracelet_with_vision_link.dae" />
        </geometry>
      </collision>
    </link>
    </xacro:if>
    <xacro:unless value="${vision}">
    <link name="${prefix}bracelet_link">
      <inertial>
        <origin xyz="-9.3E-05 0.000132 -0.022905" rpy="0 0 0" />
        <mass value="0.364" />
        <inertia ixx="0.000214" ixy="0" ixz="1E-06" iyy="0.000223" iyz="-2E-06" izz="0.00024" />
      </inertial>
      <visual>
        <origin xyz="0 0 0" rpy="0 0 0" />
        <geometry>
          <mesh filename="file://$(find kortex_description)/arms/gen3/${dof}dof/meshes/bracelet_no_vision_link.dae" />
        </geometry>
        <material name="">
          <color rgba="0.75294 0.75294 0.75294 1" />
        </material>
      </visual>
      <collision>
        <origin xyz="0 0 0" rpy="0 0 0" />
        <geometry>
          <mesh filename="file://$(find kortex_description)/arms/gen3/${dof}dof/meshes/bracelet_no_vision_link.dae" />
        </geometry>
      </collision>
    </link>
    </xacro:unless>
    <xacro:if value="${use_external_cable}">
      <joint name="${prefix}joint_7" type="revolute">
        <origin xyz="0.0003098 -0.10591859942514348 -1.855004187559394e-05" rpy="-1.5716126001303847 -0.0002182892027247651 0.002942705255619325" />
        <parent link="${prefix}spherical_wrist_2_link" />
        <child link="${prefix}bracelet_link" />
        <axis xyz="0 0 1" />
        <limit lower="${-2*PI}" upper="${2*PI}" effort="9" velocity="1.2218" />
      </joint>
    </xacro:if>
    <xacro:unless value="${use_external_cable}">
      <joint name="${prefix}joint_7" type="continuous">
        <origin xyz="0.0003098 -0.10591859942514348 -1.855004187559394e-05" rpy="-1.5716126001303847 -0.0002182892027247651 0.002942705255619325" />
        <parent link="${prefix}spherical_wrist_2_link" />
        <child link="${prefix}bracelet_link" />
        <axis xyz="0 0 1" />
        <limit effort="9" velocity="1.2218" />
      </joint>
    </xacro:unless>

    
    <link name="${prefix}end_effector_link" />
    <joint name="${prefix}end_effector_link_joint" type="fixed">
      <origin xyz="0 0 -0.0615250000000001" rpy="3.14159265358979 1.09937075168372E-32 0" />
      <parent link="${prefix}bracelet_link" />
      <child link="${prefix}end_effector_link" />
      <axis xyz="0 0 0" />
    </joint>


    <link name="${prefix}end_effector" />
    <joint name="${prefix}end_effector_joint" type="fixed">
      <origin xyz="0 0 0.18262" rpy="0 0 0" />
      <parent link="${prefix}end_effector_link" />
      <child link="${prefix}end_effector" />
      <axis xyz="0 0 0" />
    </joint>

    <xacro:if value="${vision}">
      <xacro:if value="${sim_ignition}">
        <link name="${prefix}camera_link" />
        <joint name="${prefix}camera_module" type="fixed">
          <origin xyz="0 0.05639 0.01305" rpy="0 ${-PI/2} ${-PI/2}" />
          <parent link="${prefix}end_effector_link" />
          <child link="${prefix}camera_link" />
        </joint>
        <link name="${prefix}camera_depth_frame" />
        <joint name="${prefix}depth_module" type="fixed">
          <origin xyz="0.0275 0.066 0.01305" rpy="0 ${-PI/2} ${-PI/2}" />
          <parent link="${prefix}end_effector_link" />
          <child link="${prefix}camera_depth_frame" />
        </joint>
        <link name="${prefix}camera_color_frame" />
        <joint name="${prefix}color_module" type="fixed">
          <origin xyz="0 0.05639 0.01305" rpy="0 ${-PI/2} ${-PI/2}" />
          <parent link="${prefix}end_effector_link" />
          <child link="${prefix}camera_color_frame" />
        </joint>
      </xacro:if>
      <xacro:unless value="${sim_ignition}">
        <link name="${prefix}camera_link" />
        <joint name="${prefix}camera_module" type="fixed">
          <origin xyz="0 0.05639 -0.00305" rpy="${PI} ${PI} 0" />
          <parent link="${prefix}end_effector_link" />
          <child link="${prefix}camera_link" />
        </joint>
        <link name="${prefix}camera_depth_frame" />
        <joint name="${prefix}depth_module" type="fixed">
          <origin xyz="0.0275 0.066 -0.00305" rpy="${PI} ${PI} 0" />
          <parent link="${prefix}end_effector_link" />
          <child link="${prefix}camera_depth_frame" />
        </joint>
        <link name="${prefix}camera_color_frame" />
        <joint name="${prefix}color_module" type="fixed">
          <origin xyz="0 0.05639 -0.00305" rpy="${PI} ${PI} 0" />
          <parent link="${prefix}end_effector_link" />
          <child link="${prefix}camera_color_frame" />
        </joint>
      </xacro:unless>
    </xacro:if>
  </xacro:macro>
</robot>